Workbook

Sheet Cover
B2: ADMINISTRATIVO - financial model (pre-seed)
B3: HR & administration SaaS for Romanian SMEs - administrativo.ro
B4: Prepared | C4: 7 Oct 2026
B5: Currency | C5: EUR (RON converted at 5.0 RON = 1 EUR, Assumptions!in_FX)
B6: Status on 6 Oct 2026 | C6: Product live since early Sept 2026; ZERO paying customers; free pilots only
B8: SCENARIO SELECTOR (1 = Base, 2 = Conservative, 3 = Upside) | C8: 1 | D8: =INDEX(Scenarios!$C$4:$E$4,1,C8) -> Base
B10: Key outputs (selected scenario, PROJECTION)
B11: Round size | C11: =in_Round -> 150000
B12: Pre-money / post-money valuation | C12: ="€"&TEXT(in_PreMoney,"#,##0")&" / €"&TEXT(in_PostMoney,"#,##0") -> €1,250,000 / €1,400,000
B13: Investors' ownership post-money | C13: =in_InvPct -> 0.10714286
B14: Model month 1 (assumed close) | C14: =in_StartDate -> 46388
B15: Runway with zero revenue | C15: =in_RunwayZeroRev -> 16
B16: Runway on plan | C16: =in_RunwayPlan -> 24
B17: Paying customers, month 12 / 24 / 36 | C17: =TEXT(Revenue!N21,"0")&" / "&TEXT(Revenue!Z21,"0")&" / "&TEXT(Revenue!AL21,"0") -> 47 / 139 / 284
B18: MRR month 12 | C18: =Revenue!N26 -> 2254.4027
B19: MRR month 24 | C19: =Revenue!Z26 -> 6941.1858
B20: MRR month 36 | C20: =Revenue!AL26 -> 14880.575
B21: ARR month 36 | C21: =Revenue!AL27 -> 178566.9
B22: Break-even month (model month #) | C22: =in_Breakeven -> not within 36 months
B23: Cash low point | C23: =in_CashLow -> -50706.401
B24: Months to 30 / 100 / 300 paying customers | C24: =in_M30&" / "&in_M100&" / "&in_M300 -> 8 / 20 / not within 36 months
B25: Blended ARPA (year 2) / LTV / CAC | C25: ="€"&TEXT(in_ARPA,"0")&" / €"&TEXT(in_LTV,"#,##0")&" / €"&TEXT(in_CAC,"#,##0") -> €50 / €1,583 / €497
B26: LTV/CAC, CAC payback | C26: =TEXT(in_LTVCAC,"0.0")&"x, "&TEXT(in_Payback,"0.0")&" months" -> 3.2x, 10.5 months
B27: Integrity checks (plan mix = 100%, EBITDA check = 0) | C27: =IF(AND(ROUND(in_MixCheck,6)=1,in_MaxCheck=0),"OK","CHECK") -> OK
B29: Legend
B30: Blue text | C30: hard-coded input - edit on Assumptions / Scenarios
B31: Green text | C31: link to another sheet
B32: Black text | C32: formula
B33: Yellow fill | C33: key lever (scenario, round, valuation, ESOP)
B35: Honesty notes
B36: All figures after 6 Oct 2026 are PROJECTIONS built bottom-up from pilots -> accountant partners -> direct trials. No revenue exists today.
B37: Payroll is built, undergoing accountant validation; the Finance package share is kept low.
B38: Prices above 20 employees are not published; larger firms are modelled at list price.
B39: No billing integration exists in code yet; payment fees are an assumption.
B40: Salaries, conversion rates and partner productivity are founders' assumptions (no external source).
B41: Lean pre-seed cost plan: co-founders on lean salaries, partner manager and support specialist part-time first (partner signings scaled to the manager's hours), developer hired only after the seed.
B42: [TO CONFIRM]: legal entity and registered office (VV requires Arad, Caraș-Severin, Hunedoara or Timiș), tax regime, social parts.
B43: Sheets: Assumptions -> Revenue -> Costs -> P&L & Cash -> Unit economics; Scenarios; Use of funds; Cap table; Sources.

Sheet Assumptions
A1: Assumptions - every driver of the model
A2: Blue = hard-coded input (edit here). Green = picked from 'Scenarios' for the scenario chosen on Cover. Black = calculated. Yellow = key lever. Nothing on other sheets is hard-coded.
A4: Driver | B4: Value | C4: Unit | D4: Source / note
A6: General
A7: Exchange rate RON per EUR | B7: 5 | C7: RON/EUR | D7: Convention used in every document of this application.
A8: Model month 1 | B8: 46388 | C8: date | D8: Model starts Jan 2027 = assumed close of the round. VV Accelerator Cohort 3 date is NOT published (vestventures.vc, 6 Oct 2026) -> if the close slips, the whole timeline shifts.
A9: Month the round is received | B9: 1 | C9: model month | D9: ASSUMPTION; see StartDate.
A10: Cash in the company before the round | B10: 0 | C10: EUR | D10: [TO CONFIRM] by the founders. Set to 0 (prudent).
A12: Round (key levers)
A13: Vest Ventures accelerator ticket | B13: 135000 | C13: EUR | D13: VV Accelerator ticket EUR 10k-200k, de minimis, >=10% independent private co-investment (vestventures.vc/en/programs-terms). EUR 135k requested, inside the range.
A14: Independent private co-investors (business angels) | B14: 15000 | C14: EUR | D14: 10% of the round (11.1% of the VV ticket): meets VV's >=10% private co-investment rule whether it is measured on the total (exactly, no margin) or on VV's ticket - basis [TO CONFIRM] with VV. Angels NOT identified yet.
A15: Round size (VV ticket + angels) | B15: =in_VVTicket+in_Angels -> 150000 | C15: EUR | D15: Calculated. Target range given by the founders: EUR 150k-300k pre-seed.
A16: Minimum private co-investment (VV rule, as % of VV ticket) | B16: 0.1 | C16: % | D16: Vest Ventures programme terms ('>=10% private co-investment'). Basis of the 10% (ticket vs total) [TO CONFIRM] with VV.
A17: Pre-money valuation (fully diluted, incl. new ESOP) | B17: 1250000 | C17: EUR | D17: Founders' proposal. We found no sourced RO/CEE pre-seed valuation benchmark; DERIVED range EUR 0.75-3M post.
A18: Employee option pool, % of post-money (created pre-money) | B18: 0.1 | C18: % | D18: Created before the round so it dilutes founders only (standard 'pre-money pool'). SRL needs a phantom/virtual scheme until SRL->SA [TO CONFIRM].
A20: Pricing (list prices, RON/month, final - seller not VAT-registered)
A21: HR core (attendance, leave, personnel file, employee portal) | B21: 149 | C21: RON/month | D21: Public price list, administrativo.ro/en/preturi
A22: Extended HR package (core + REGES, onboarding, courses, SSM, evaluations, KPI) | B22: 249 | C22: RON/month | D22: Public price list, administrativo.ro/en/preturi
A23: Operations package (core + fleet, maintenance, inventory, announcements, ticketing) | B23: 229 | C23: RON/month | D23: Public price list, administrativo.ro/en/preturi
A24: Finance package (core + payroll, per diem, reports) | B24: 219 | C24: RON/month | D24: Public price list, administrativo.ro/en/preturi
A25: Whole application (all 15 add-ons) | B25: 499 | C25: RON/month | D25: Public price list, administrativo.ro/en/preturi
A27: Plan mix of paying customers (must sum to 100%)
A28: Share on HR core | B28: 0.45 | C28: % | D28: ASSUMPTION.
A29: Share on Extended HR package | B29: 0.25 | C29: % | D29: ASSUMPTION.
A30: Share on Operations package | B30: 0.1 | C30: % | D30: ASSUMPTION.
A31: Share on Finance package | B31: 0.05 | C31: % | D31: ASSUMPTION. Payroll (Finance) kept low: payroll is built, undergoing accountant validation.
A32: Share on Whole application | B32: 0.15 | C32: % | D32: ASSUMPTION.
A33: Check: plan mix total | B33: =in_MixCore+in_MixExtHR+in_MixOps+in_MixFin+in_MixAll -> 1 | C33: % | D33: Must equal 100%.
A34: Blended list price per paying customer (year 1) | B34: =in_PriceCore*in_MixCore+in_PriceExtHR*in_MixExtHR+in_PriceOps*in_MixOps+in_PriceFin*in_MixFin+in_PriceAll*in_MixAll -> 238 | C34: RON/month | D34: Calculated = sum(price x mix). Firms above 20 employees have no published price -> modelled at list price (understates revenue from larger firms).
A35: Blended ARPA, year 1 | B35: =in_BlendedPriceRON/in_FX -> 47.6 | C35: EUR/month
A37: Channels and timing
A38: Month pilot companies start paying | B38: 4 | C38: model month | D38: Apr 2027: pilot is free until 31 Mar 2027 (administrativo.ro/pentru-contabili).
A39: First month new partners are signed | B39: 4 | C39: model month | D39: One month after the partner manager starts (in_SalesStart).
A40: Share of marketing budget spent on performance ads | B40: 0.6 | C40: % | D40: Rest is content/SEO/events material. ASSUMPTION.
A41: Accountant commission on referred subscription | B41: 0.2 | C41: % | D41: 20% for 6 months from first paid month (administrativo.ro/pentru-contabili).
A42: Commission duration | B42: 6 | C42: months | D42: administrativo.ro/pentru-contabili.
A44: Team (gross monthly salary, EUR; employer adds CAM)
A45: Employer contribution on gross (CAM) | B45: 0.0225 | C45: % | D45: Romanian 'contribuția asiguratorie pentru muncă' 2.25% - legal value [TO CONFIRM] by accountant.
A46: Annual salary increase (from year 2) | B46: 0.05 | C46: % | D46: ASSUMPTION.
A47: Co-founder gross salary (each, 2 people) | B47: 1000 | C47: EUR/month | D47: Both co-founders full time from close, on a deliberately lean pre-seed salary (~RON 5,000 gross) to stretch the runway; kept at this level in the model (only the annual raise applies). ASSUMPTION - no sourced salary benchmark.
...

Sheet Revenue
A1: Revenue - customers, MRR, ARR (PROJECTION, selected scenario)
A2: Month 1 = Jan 2027 = assumed close of the round. Zero paying customers on 6 Oct 2026. Customers are expected values (fractions allowed). EUR at in_FX RON/EUR.
A3: Month # | C3: 1 | D3: =C3+1 -> 2 | E3: =D3+1 -> 3 | F3: =E3+1 -> 4 | G3: =F3+1 -> 5 | H3: =G3+1 -> 6 | I3: =H3+1 -> 7 | J3: =I3+1 -> 8 | K3: =J3+1 -> 9 | ... AL3: =AK3+1 -> 36
A4: Month | C4: =DATE(YEAR(in_StartDate),MONTH(in_StartDate)+C3-1,1) -> 46388 | D4: =DATE(YEAR(in_StartDate),MONTH(in_StartDate)+D3-1,1) -> 46419 | E4: =DATE(YEAR(in_StartDate),MONTH(in_StartDate)+E3-1,1) -> 46447 | F4: =DATE(YEAR(in_StartDate),MONTH(in_StartDate)+F3-1,1) -> 46478 | G4: =DATE(YEAR(in_StartDate),MONTH(in_StartDate)+G3-1,1) -> 46508 | H4: =DATE(YEAR(in_StartDate),MONTH(in_StartDate)+H3-1,1) -> 46539 | I4: =DATE(YEAR(in_StartDate),MONTH(in_StartDate)+I3-1,1) -> 46569 | J4: =DATE(YEAR(in_StartDate),MONTH(in_StartDate)+J3-1,1) -> 46600 | ... AL4: =DATE(YEAR(in_StartDate),MONTH(in_StartDate)+AL3-1,1) -> 47453
A5: Model year | C5: =INT((C3-1)/12)+1 -> 1 | D5: =INT((D3-1)/12)+1 -> 1 | E5: =INT((E3-1)/12)+1 -> 1 | F5: =INT((F3-1)/12)+1 -> 1 | G5: =INT((G3-1)/12)+1 -> 1 | H5: =INT((H3-1)/12)+1 -> 1 | I5: =INT((I3-1)/12)+1 -> 1 | J5: =INT((J3-1)/12)+1 -> 1 | ... AL5: =INT((AL3-1)/12)+1 -> 3
A7: Acquisition channels
A8: Pilot companies converting to paid | B8: firms | C8: =IF(C$3=in_PilotConvMonth,in_PilotPractices*in_PilotFirmsPerPractice*in_PilotConv,0) -> 0 | D8: =IF(D$3=in_PilotConvMonth,in_PilotPractices*in_PilotFirmsPerPractice*in_PilotConv,0) -> 0 | E8: =IF(E$3=in_PilotConvMonth,in_PilotPractices*in_PilotFirmsPerPractice*in_PilotConv,0) -> 0 | F8: =IF(F$3=in_PilotConvMonth,in_PilotPractices*in_PilotFirmsPerPractice*in_PilotConv,0) -> 6 | G8: =IF(G$3=in_PilotConvMonth,in_PilotPractices*in_PilotFirmsPerPractice*in_PilotConv,0) -> 0 | H8: =IF(H$3=in_PilotConvMonth,in_PilotPractices*in_PilotFirmsPerPractice*in_PilotConv,0) -> 0 | I8: =IF(I$3=in_PilotConvMonth,in_PilotPractices*in_PilotFirmsPerPractice*in_PilotConv,0) -> 0 | J8: =IF(J$3=in_PilotConvMonth,in_PilotPractices*in_PilotFirmsPerPractice*in_PilotConv,0) -> 0 | ... AL8: =IF(AL$3=in_PilotConvMonth,in_PilotPractices*in_PilotFirmsPerPractice*in_PilotConv,0) -> 0
A9: New accountant partners signed (x partner manager FTE) | B9: practices | C9: =IF(C$3>=in_PartnerStart,CHOOSE(C$5,in_NewPartnersY1,in_NewPartnersY2,in_NewPartnersY3)*IF(C$3>=in_SalesFullStart,1,in_SalesFTE),0) -> 0 | D9: =IF(D$3>=in_PartnerStart,CHOOSE(D$5,in_NewPartnersY1,in_NewPartnersY2,in_NewPartnersY3)*IF(D$3>=in_SalesFullStart,1,in_SalesFTE),0) -> 0 | E9: =IF(E$3>=in_PartnerStart,CHOOSE(E$5,in_NewPartnersY1,in_NewPartnersY2,in_NewPartnersY3)*IF(E$3>=in_SalesFullStart,1,in_SalesFTE),0) -> 0 | F9: =IF(F$3>=in_PartnerStart,CHOOSE(F$5,in_NewPartnersY1,in_NewPartnersY2,in_NewPartnersY3)*IF(F$3>=in_SalesFullStart,1,in_SalesFTE),0) -> 1 | G9: =IF(G$3>=in_PartnerStart,CHOOSE(G$5,in_NewPartnersY1,in_NewPartnersY2,in_NewPartnersY3)*IF(G$3>=in_SalesFullStart,1,in_SalesFTE),0) -> 1 | H9: =IF(H$3>=in_PartnerStart,CHOOSE(H$5,in_NewPartnersY1,in_NewPartnersY2,in_NewPartnersY3)*IF(H$3>=in_SalesFullStart,1,in_SalesFTE),0) -> 1 | I9: =IF(I$3>=in_PartnerStart,CHOOSE(I$5,in_NewPartnersY1,in_NewPartnersY2,in_NewPartnersY3)*IF(I$3>=in_SalesFullStart,1,in_SalesFTE),0) -> 1 | J9: =IF(J$3>=in_PartnerStart,CHOOSE(J$5,in_NewPartnersY1,in_NewPartnersY2,in_NewPartnersY3)*IF(J$3>=in_SalesFullStart,1,in_SalesFTE),0) -> 1 | ... AL9: =IF(AL$3>=in_PartnerStart,CHOOSE(AL$5,in_NewPartnersY1,in_NewPartnersY2,in_NewPartnersY3)*IF(AL$3>=in_SalesFullStart,1,in_SalesFTE),0) -> 4
A10: Active accountant partners (end of month) | B10: practices | C10: =0+C9+IF(C$3=in_PilotConvMonth,in_PilotPractices,0) -> 0 | D10: =C10+D9+IF(D$3=in_PilotConvMonth,in_PilotPractices,0) -> 0 | E10: =D10+E9+IF(E$3=in_PilotConvMonth,in_PilotPractices,0) -> 0 | F10: =E10+F9+IF(F$3=in_PilotConvMonth,in_PilotPractices,0) -> 7 | G10: =F10+G9+IF(G$3=in_PilotConvMonth,in_PilotPractices,0) -> 8 | H10: =G10+H9+IF(H$3=in_PilotConvMonth,in_PilotPractices,0) -> 9 | I10: =H10+I9+IF(I$3=in_PilotConvMonth,in_PilotPractices,0) -> 10 | J10: =I10+J9+IF(J$3=in_PilotConvMonth,in_PilotPractices,0) -> 11 | K10: =J10+K9+IF(K$3=in_PilotConvMonth,in_PilotPractices,0) -> 12 | ... AL10: =AK10+AL9+IF(AL$3=in_PilotConvMonth,in_PilotPractices,0) -> 99
A11: Firms referred by partners | B11: firms | C11: =0*in_RefRate -> 0 | D11: =C10*in_RefRate -> 0 | E11: =D10*in_RefRate -> 0 | F11: =E10*in_RefRate -> 0 | G11: =F10*in_RefRate -> 1.4 | H11: =G10*in_RefRate -> 1.6 | I11: =H10*in_RefRate -> 1.8 | J11: =I10*in_RefRate -> 2 | K11: =J10*in_RefRate -> 2.2 | ... AL11: =AK10*in_RefRate -> 19
A12: New paying customers - partner referrals (after free month) | B12: firms | C12: =0*in_RefConv -> 0 | D12: =C11*in_RefConv -> 0 | E12: =D11*in_RefConv -> 0 | F12: =E11*in_RefConv -> 0 | G12: =F11*in_RefConv -> 0 | H12: =G11*in_RefConv -> 0.7 | I12: =H11*in_RefConv -> 0.8 | J12: =I11*in_RefConv -> 0.9 | K12: =J11*in_RefConv -> 1 | ... AL12: =AK11*in_RefConv -> 9.1
A13: Organic / SEO / direct trials | B13: trials | C13: =CHOOSE(C$5,in_OrganicY1,in_OrganicY2,in_OrganicY3) -> 4 | D13: =CHOOSE(D$5,in_OrganicY1,in_OrganicY2,in_OrganicY3) -> 4 | E13: =CHOOSE(E$5,in_OrganicY1,in_OrganicY2,in_OrganicY3) -> 4 | F13: =CHOOSE(F$5,in_OrganicY1,in_OrganicY2,in_OrganicY3) -> 4 | G13: =CHOOSE(G$5,in_OrganicY1,in_OrganicY2,in_OrganicY3) -> 4 | H13: =CHOOSE(H$5,in_OrganicY1,in_OrganicY2,in_OrganicY3) -> 4 | I13: =CHOOSE(I$5,in_OrganicY1,in_OrganicY2,in_OrganicY3) -> 4 | J13: =CHOOSE(J$5,in_OrganicY1,in_OrganicY2,in_OrganicY3) -> 4 | ... AL13: =CHOOSE(AL$5,in_OrganicY1,in_OrganicY2,in_OrganicY3) -> 20
A14: Paid-marketing trials | B14: trials | C14: =Costs!C21*in_PaidShare/in_CostPerTrial -> 11.25 | D14: =Costs!D21*in_PaidShare/in_CostPerTrial -> 11.25 | E14: =Costs!E21*in_PaidShare/in_CostPerTrial -> 11.25 | F14: =Costs!F21*in_PaidShare/in_CostPerTrial -> 11.25 | G14: =Costs!G21*in_PaidShare/in_CostPerTrial -> 11.25 | H14: =Costs!H21*in_PaidShare/in_CostPerTrial -> 11.25 | I14: =Costs!I21*in_PaidShare/in_CostPerTrial -> 11.25 | J14: =Costs!J21*in_PaidShare/in_CostPerTrial -> 11.25 | ... AL14: =Costs!AL21*in_PaidShare/in_CostPerTrial -> 26.25
A15: New paying customers - direct (after free month) | B15: firms | C15: =(0+0)*in_TrialConv -> 0 | D15: =(C13+C14)*in_TrialConv -> 3.8125 | E15: =(D13+D14)*in_TrialConv -> 3.8125 | F15: =(E13+E14)*in_TrialConv -> 3.8125 | G15: =(F13+F14)*in_TrialConv -> 3.8125 | H15: =(G13+G14)*in_TrialConv -> 3.8125 | I15: =(H13+H14)*in_TrialConv -> 3.8125 | J15: =(I13+I14)*in_TrialConv -> 3.8125 | K15: =(J13+J14)*in_TrialConv -> 3.8125 | ... AL15: =(AK13+AK14)*in_TrialConv -> 11.5625
A17: Customers
A18: New paying customers - total | B18: firms | C18: =C8+C12+C15 -> 0 | D18: =D8+D12+D15 -> 3.8125 | E18: =E8+E12+E15 -> 3.8125 | F18: =F8+F12+F15 -> 9.8125 | G18: =G8+G12+G15 -> 3.8125 | H18: =H8+H12+H15 -> 4.5125 | I18: =I8+I12+I15 -> 4.6125 | J18: =J8+J12+J15 -> 4.7125 | ... AL18: =AL8+AL12+AL15 -> 20.6625
A19: of which via accountants (pilot + partners) | B19: firms | C19: =C8+C12 -> 0 | D19: =D8+D12 -> 0 | E19: =E8+E12 -> 0 | F19: =F8+F12 -> 6 | G19: =G8+G12 -> 0 | H19: =H8+H12 -> 0.7 | I19: =I8+I12 -> 0.8 | J19: =J8+J12 -> 0.9 | ... AL19: =AL8+AL12 -> 9.1
A20: Churned customers | B20: firms | C20: =0*in_Churn -> 0 | D20: =C21*in_Churn -> 0 | E20: =D21*in_Churn -> 0.114375 | F20: =E21*in_Churn -> 0.22531875 | G20: =F21*in_Churn -> 0.51293419 | H20: =G21*in_Churn -> 0.61192116 | I20: =H21*in_Churn -> 0.72893853 | J20: =I21*in_Churn -> 0.84544537 | K20: =J21*in_Churn -> 0.96145701 | ... AL20: =AK21*in_Churn -> 8.1306324
A21: Paying customers (end of month) | B21: firms | C21: =0+C18-C20 -> 0 | D21: =C21+D18-D20 -> 3.8125 | E21: =D21+E18-E20 -> 7.510625 | F21: =E21+F18-F20 -> 17.097806 | G21: =F21+G18-G20 -> 20.397372 | H21: =G21+H18-H20 -> 24.297951 | I21: =H21+I18-I20 -> 28.181512 | J21: =I21+J18-J20 -> 32.048567 | K21: =J21+K18-K20 -> 35.89961 | ... AL21: =AK21+AL18-AL20 -> 283.55295
A23: Revenue
A24: Blended list price | B24: RON/month | C24: =in_BlendedPriceRON*(1+in_PriceInc)^(C$5-1) -> 238 | D24: =in_BlendedPriceRON*(1+in_PriceInc)^(D$5-1) -> 238 | E24: =in_BlendedPriceRON*(1+in_PriceInc)^(E$5-1) -> 238 | F24: =in_BlendedPriceRON*(1+in_PriceInc)^(F$5-1) -> 238 | G24: =in_BlendedPriceRON*(1+in_PriceInc)^(G$5-1) -> 238 | H24: =in_BlendedPriceRON*(1+in_PriceInc)^(H$5-1) -> 238 | I24: =in_BlendedPriceRON*(1+in_PriceInc)^(I$5-1) -> 238 | J24: =in_BlendedPriceRON*(1+in_PriceInc)^(J$5-1) -> 238 | ... AL24: =in_BlendedPriceRON*(1+in_PriceInc)^(AL$5-1) -> 262.395
A25: ARPA | B25: EUR/month | C25: =C24/in_FX -> 47.6 | D25: =D24/in_FX -> 47.6 | E25: =E24/in_FX -> 47.6 | F25: =F24/in_FX -> 47.6 | G25: =G24/in_FX -> 47.6 | H25: =H24/in_FX -> 47.6 | I25: =I24/in_FX -> 47.6 | J25: =J24/in_FX -> 47.6 | ... AL25: =AL24/in_FX -> 52.479
A26: MRR | B26: EUR | C26: =C21*C25 -> 0 | D26: =D21*D25 -> 181.475 | E26: =E21*E25 -> 357.50575 | F26: =F21*F25 -> 813.85558 | G26: =G21*G25 -> 970.91491 | H26: =H21*H25 -> 1156.5825 | I26: =I21*I25 -> 1341.44 | J26: =J21*J25 -> 1525.5118 | ... AL26: =AL21*AL25 -> 14880.575
A27: ARR (MRR x 12) | B27: EUR | C27: =C26*12 -> 0 | D27: =D26*12 -> 2177.7 | E27: =E26*12 -> 4290.069 | F27: =F26*12 -> 9766.2669 | G27: =G26*12 -> 11650.979 | H27: =H26*12 -> 13878.99 | I27: =I26*12 -> 16097.28 | J27: =J26*12 -> 18306.141 | ... AL27: =AL26*12 -> 178566.9
A28: Revenue recognised (billed monthly) | B28: EUR | C28: =C26 -> 0 | D28: =D26 -> 181.475 | E28: =E26 -> 357.50575 | F28: =F26 -> 813.85558 | G28: =G26 -> 970.91491 | H28: =H26 -> 1156.5825 | I28: =I26 -> 1341.44 | J28: =J26 -> 1525.5118 | ... AL28: =AL26 -> 14880.575
A30: Milestones (selected scenario)
A31: First month with >= 30 paying customers | B31: 30 | C31: =IF(MAX(Revenue!$C$21:$AL$21)<B31,"not within 36 months",COUNTIF(Revenue!$C$21:$AL$21,"<"&B31)+1) -> 8 | D31: =IF(ISNUMBER(C31),INDEX(Revenue!$C$4:$AL$4,1,C31),"-") -> 46600 | E31: month #, date (COUNTIF works because the customer curve is non-decreasing)
A32: First month with >= 100 paying customers | B32: 100 | C32: =IF(MAX(Revenue!$C$21:$AL$21)<B32,"not within 36 months",COUNTIF(Revenue!$C$21:$AL$21,"<"&B32)+1) -> 20 | D32: =IF(ISNUMBER(C32),INDEX(Revenue!$C$4:$AL$4,1,C32),"-") -> 46966 | E32: month #, date (COUNTIF works because the customer curve is non-decreasing)
A33: First month with >= 300 paying customers | B33: 300 | C33: =IF(MAX(Revenue!$C$21:$AL$21)<B33,"not within 36 months",COUNTIF(Revenue!$C$21:$AL$21,"<"&B33)+1) -> not within 36 months | D33: =IF(ISNUMBER(C33),INDEX(Revenue!$C$4:$AL$4,1,C33),"-") -> - | E33: month #, date (COUNTIF works because the customer curve is non-decreasing)

Sheet Costs
A1: Costs - headcount plan and operating expenses (EUR, PROJECTION)
A2: Salaries = gross x (1 + CAM) x (1 + raise)^(year-1). One-off items are spread evenly between their start and end month.
A3: Month # | C3: =Revenue!C3 -> 1 | D3: =Revenue!D3 -> 2 | E3: =Revenue!E3 -> 3 | F3: =Revenue!F3 -> 4 | G3: =Revenue!G3 -> 5 | H3: =Revenue!H3 -> 6 | I3: =Revenue!I3 -> 7 | J3: =Revenue!J3 -> 8 | ... AL3: =Revenue!AL3 -> 36
A4: Month | C4: =Revenue!C4 -> 46388 | D4: =Revenue!D4 -> 46419 | E4: =Revenue!E4 -> 46447 | F4: =Revenue!F4 -> 46478 | G4: =Revenue!G4 -> 46508 | H4: =Revenue!H4 -> 46539 | I4: =Revenue!I4 -> 46569 | J4: =Revenue!J4 -> 46600 | ... AL4: =Revenue!AL4 -> 47453
A5: Model year | C5: =Revenue!C5 -> 1 | D5: =Revenue!D5 -> 1 | E5: =Revenue!E5 -> 1 | F5: =Revenue!F5 -> 1 | G5: =Revenue!G5 -> 1 | H5: =Revenue!H5 -> 1 | I5: =Revenue!I5 -> 1 | J5: =Revenue!J5 -> 1 | ... AL5: =Revenue!AL5 -> 3
A7: Headcount (employer cost)
A8: Co-founder - Miroslav Maletici (role [TO CONFIRM]) | B8: EUR | C8: =IF(C$3>=1,in_SalFounder*(1+in_CAM)*(1+in_Raise)^(C$5-1),0) -> 1022.5 | D8: =IF(D$3>=1,in_SalFounder*(1+in_CAM)*(1+in_Raise)^(D$5-1),0) -> 1022.5 | E8: =IF(E$3>=1,in_SalFounder*(1+in_CAM)*(1+in_Raise)^(E$5-1),0) -> 1022.5 | F8: =IF(F$3>=1,in_SalFounder*(1+in_CAM)*(1+in_Raise)^(F$5-1),0) -> 1022.5 | G8: =IF(G$3>=1,in_SalFounder*(1+in_CAM)*(1+in_Raise)^(G$5-1),0) -> 1022.5 | H8: =IF(H$3>=1,in_SalFounder*(1+in_CAM)*(1+in_Raise)^(H$5-1),0) -> 1022.5 | I8: =IF(I$3>=1,in_SalFounder*(1+in_CAM)*(1+in_Raise)^(I$5-1),0) -> 1022.5 | J8: =IF(J$3>=1,in_SalFounder*(1+in_CAM)*(1+in_Raise)^(J$5-1),0) -> 1022.5 | ... AL8: =IF(AL$3>=1,in_SalFounder*(1+in_CAM)*(1+in_Raise)^(AL$5-1),0) -> 1127.3063
A9: Co-founder - Răzvan Pervulescu (role [TO CONFIRM]) | B9: EUR | C9: =IF(C$3>=1,in_SalFounder*(1+in_CAM)*(1+in_Raise)^(C$5-1),0) -> 1022.5 | D9: =IF(D$3>=1,in_SalFounder*(1+in_CAM)*(1+in_Raise)^(D$5-1),0) -> 1022.5 | E9: =IF(E$3>=1,in_SalFounder*(1+in_CAM)*(1+in_Raise)^(E$5-1),0) -> 1022.5 | F9: =IF(F$3>=1,in_SalFounder*(1+in_CAM)*(1+in_Raise)^(F$5-1),0) -> 1022.5 | G9: =IF(G$3>=1,in_SalFounder*(1+in_CAM)*(1+in_Raise)^(G$5-1),0) -> 1022.5 | H9: =IF(H$3>=1,in_SalFounder*(1+in_CAM)*(1+in_Raise)^(H$5-1),0) -> 1022.5 | I9: =IF(I$3>=1,in_SalFounder*(1+in_CAM)*(1+in_Raise)^(I$5-1),0) -> 1022.5 | J9: =IF(J$3>=1,in_SalFounder*(1+in_CAM)*(1+in_Raise)^(J$5-1),0) -> 1022.5 | ... AL9: =IF(AL$3>=1,in_SalFounder*(1+in_CAM)*(1+in_Raise)^(AL$5-1),0) -> 1127.3063
A10: Partner & sales manager (accountant channel; part-time first) | B10: EUR | C10: =IF(C$3>=in_SalesStart,in_SalSales*IF(C$3>=in_SalesFullStart,1,in_SalesFTE)*(1+in_CAM)*(1+in_Raise)^(C$5-1),0) -> 0 | D10: =IF(D$3>=in_SalesStart,in_SalSales*IF(D$3>=in_SalesFullStart,1,in_SalesFTE)*(1+in_CAM)*(1+in_Raise)^(D$5-1),0) -> 0 | E10: =IF(E$3>=in_SalesStart,in_SalSales*IF(E$3>=in_SalesFullStart,1,in_SalesFTE)*(1+in_CAM)*(1+in_Raise)^(E$5-1),0) -> 1022.5 | F10: =IF(F$3>=in_SalesStart,in_SalSales*IF(F$3>=in_SalesFullStart,1,in_SalesFTE)*(1+in_CAM)*(1+in_Raise)^(F$5-1),0) -> 1022.5 | G10: =IF(G$3>=in_SalesStart,in_SalSales*IF(G$3>=in_SalesFullStart,1,in_SalesFTE)*(1+in_CAM)*(1+in_Raise)^(G$5-1),0) -> 1022.5 | H10: =IF(H$3>=in_SalesStart,in_SalSales*IF(H$3>=in_SalesFullStart,1,in_SalesFTE)*(1+in_CAM)*(1+in_Raise)^(H$5-1),0) -> 1022.5 | I10: =IF(I$3>=in_SalesStart,in_SalSales*IF(I$3>=in_SalesFullStart,1,in_SalesFTE)*(1+in_CAM)*(1+in_Raise)^(I$5-1),0) -> 1022.5 | J10: =IF(J$3>=in_SalesStart,in_SalSales*IF(J$3>=in_SalesFullStart,1,in_SalesFTE)*(1+in_CAM)*(1+in_Raise)^(J$5-1),0) -> 1022.5 | ... AL10: =IF(AL$3>=in_SalesStart,in_SalSales*IF(AL$3>=in_SalesFullStart,1,in_SalesFTE)*(1+in_CAM)*(1+in_Raise)^(AL$5-1),0) -> 2254.6125
A11: Customer onboarding & support specialist (part-time first) | B11: EUR | C11: =IF(C$3>=in_SupportStart,in_SalSupport*IF(C$3>=in_SupportFullStart,1,in_SupportFTE)*(1+in_CAM)*(1+in_Raise)^(C$5-1),0) -> 0 | D11: =IF(D$3>=in_SupportStart,in_SalSupport*IF(D$3>=in_SupportFullStart,1,in_SupportFTE)*(1+in_CAM)*(1+in_Raise)^(D$5-1),0) -> 0 | E11: =IF(E$3>=in_SupportStart,in_SalSupport*IF(E$3>=in_SupportFullStart,1,in_SupportFTE)*(1+in_CAM)*(1+in_Raise)^(E$5-1),0) -> 0 | F11: =IF(F$3>=in_SupportStart,in_SalSupport*IF(F$3>=in_SupportFullStart,1,in_SupportFTE)*(1+in_CAM)*(1+in_Raise)^(F$5-1),0) -> 0 | G11: =IF(G$3>=in_SupportStart,in_SalSupport*IF(G$3>=in_SupportFullStart,1,in_SupportFTE)*(1+in_CAM)*(1+in_Raise)^(G$5-1),0) -> 0 | H11: =IF(H$3>=in_SupportStart,in_SalSupport*IF(H$3>=in_SupportFullStart,1,in_SupportFTE)*(1+in_CAM)*(1+in_Raise)^(H$5-1),0) -> 0 | I11: =IF(I$3>=in_SupportStart,in_SalSupport*IF(I$3>=in_SupportFullStart,1,in_SupportFTE)*(1+in_CAM)*(1+in_Raise)^(I$5-1),0) -> 715.75 | J11: =IF(J$3>=in_SupportStart,in_SalSupport*IF(J$3>=in_SupportFullStart,1,in_SupportFTE)*(1+in_CAM)*(1+in_Raise)^(J$5-1),0) -> 715.75 | ... AL11: =IF(AL$3>=in_SupportStart,in_SalSupport*IF(AL$3>=in_SupportFullStart,1,in_SupportFTE)*(1+in_CAM)*(1+in_Raise)^(AL$5-1),0) -> 1578.2287
A12: Full-stack developer | B12: EUR | C12: =IF(C$3>=in_DevStart,in_SalDev*(1+in_CAM)*(1+in_Raise)^(C$5-1),0) -> 0 | D12: =IF(D$3>=in_DevStart,in_SalDev*(1+in_CAM)*(1+in_Raise)^(D$5-1),0) -> 0 | E12: =IF(E$3>=in_DevStart,in_SalDev*(1+in_CAM)*(1+in_Raise)^(E$5-1),0) -> 0 | F12: =IF(F$3>=in_DevStart,in_SalDev*(1+in_CAM)*(1+in_Raise)^(F$5-1),0) -> 0 | G12: =IF(G$3>=in_DevStart,in_SalDev*(1+in_CAM)*(1+in_Raise)^(G$5-1),0) -> 0 | H12: =IF(H$3>=in_DevStart,in_SalDev*(1+in_CAM)*(1+in_Raise)^(H$5-1),0) -> 0 | I12: =IF(I$3>=in_DevStart,in_SalDev*(1+in_CAM)*(1+in_Raise)^(I$5-1),0) -> 0 | J12: =IF(J$3>=in_DevStart,in_SalDev*(1+in_CAM)*(1+in_Raise)^(J$5-1),0) -> 0 | ... AL12: =IF(AL$3>=in_DevStart,in_SalDev*(1+in_CAM)*(1+in_Raise)^(AL$5-1),0) -> 2818.2656
A13: Total headcount cost | B13: EUR | C13: =SUM(C8:C12) -> 2045 | D13: =SUM(D8:D12) -> 2045 | E13: =SUM(E8:E12) -> 3067.5 | F13: =SUM(F8:F12) -> 3067.5 | G13: =SUM(G8:G12) -> 3067.5 | H13: =SUM(H8:H12) -> 3067.5 | I13: =SUM(I8:I12) -> 3783.25 | J13: =SUM(J8:J12) -> 3783.25 | ... AL13: =SUM(AL8:AL12) -> 8905.7194
A14: Headcount (FTE) | B14: FTE | C14: =2+IF(C$3>=in_SalesStart,IF(C$3>=in_SalesFullStart,1,in_SalesFTE),0)+IF(C$3>=in_SupportStart,IF(C$3>=in_SupportFullStart,1,in_SupportFTE),0)+IF(C$3>=in_DevStart,1,0) -> 2 | D14: =2+IF(D$3>=in_SalesStart,IF(D$3>=in_SalesFullStart,1,in_SalesFTE),0)+IF(D$3>=in_SupportStart,IF(D$3>=in_SupportFullStart,1,in_SupportFTE),0)+IF(D$3>=in_DevStart,1,0) -> 2 | E14: =2+IF(E$3>=in_SalesStart,IF(E$3>=in_SalesFullStart,1,in_SalesFTE),0)+IF(E$3>=in_SupportStart,IF(E$3>=in_SupportFullStart,1,in_SupportFTE),0)+IF(E$3>=in_DevStart,1,0) -> 2.5 | F14: =2+IF(F$3>=in_SalesStart,IF(F$3>=in_SalesFullStart,1,in_SalesFTE),0)+IF(F$3>=in_SupportStart,IF(F$3>=in_SupportFullStart,1,in_SupportFTE),0)+IF(F$3>=in_DevStart,1,0) -> 2.5 | G14: =2+IF(G$3>=in_SalesStart,IF(G$3>=in_SalesFullStart,1,in_SalesFTE),0)+IF(G$3>=in_SupportStart,IF(G$3>=in_SupportFullStart,1,in_SupportFTE),0)+IF(G$3>=in_DevStart,1,0) -> 2.5 | H14: =2+IF(H$3>=in_SalesStart,IF(H$3>=in_SalesFullStart,1,in_SalesFTE),0)+IF(H$3>=in_SupportStart,IF(H$3>=in_SupportFullStart,1,in_SupportFTE),0)+IF(H$3>=in_DevStart,1,0) -> 2.5 | I14: =2+IF(I$3>=in_SalesStart,IF(I$3>=in_SalesFullStart,1,in_SalesFTE),0)+IF(I$3>=in_SupportStart,IF(I$3>=in_SupportFullStart,1,in_SupportFTE),0)+IF(I$3>=in_DevStart,1,0) -> 3 | J14: =2+IF(J$3>=in_SalesStart,IF(J$3>=in_SalesFullStart,1,in_SalesFTE),0)+IF(J$3>=in_SupportStart,IF(J$3>=in_SupportFullStart,1,in_SupportFTE),0)+IF(J$3>=in_DevStart,1,0) -> 3 | ... AL14: =2+IF(AL$3>=in_SalesStart,IF(AL$3>=in_SalesFullStart,1,in_SalesFTE),0)+IF(AL$3>=in_SupportStart,IF(AL$3>=in_SupportFullStart,1,in_SupportFTE),0)+IF(AL$3>=in_DevStart,1,0) -> 5
A16: Operating expenses
A17: Hosting & infrastructure (fixed) | B17: EUR | C17: =in_InfraFixed -> 350 | D17: =in_InfraFixed -> 350 | E17: =in_InfraFixed -> 350 | F17: =in_InfraFixed -> 350 | G17: =in_InfraFixed -> 350 | H17: =in_InfraFixed -> 350 | I17: =in_InfraFixed -> 350 | J17: =in_InfraFixed -> 350 | ... AL17: =in_InfraFixed -> 350
A18: Infrastructure (variable, per customer) | B18: EUR | C18: =Revenue!C21*in_InfraVar -> 0 | D18: =Revenue!D21*in_InfraVar -> 5.71875 | E18: =Revenue!E21*in_InfraVar -> 11.265937 | F18: =Revenue!F21*in_InfraVar -> 25.646709 | G18: =Revenue!G21*in_InfraVar -> 30.596058 | H18: =Revenue!H21*in_InfraVar -> 36.446926 | I18: =Revenue!I21*in_InfraVar -> 42.272269 | J18: =Revenue!J21*in_InfraVar -> 48.072851 | ... AL18: =Revenue!AL21*in_InfraVar -> 425.32942
A19: Development tools & AI subscriptions | B19: EUR | C19: =in_Tools -> 250 | D19: =in_Tools -> 250 | E19: =in_Tools -> 250 | F19: =in_Tools -> 250 | G19: =in_Tools -> 250 | H19: =in_Tools -> 250 | I19: =in_Tools -> 250 | J19: =in_Tools -> 250 | ... AL19: =in_Tools -> 250
A20: Payment processing fees | B20: EUR | C20: =Revenue!C28*in_PayFee -> 0 | D20: =Revenue!D28*in_PayFee -> 3.6295 | E20: =Revenue!E28*in_PayFee -> 7.150115 | F20: =Revenue!F28*in_PayFee -> 16.277112 | G20: =Revenue!G28*in_PayFee -> 19.418298 | H20: =Revenue!H28*in_PayFee -> 23.131649 | I20: =Revenue!I28*in_PayFee -> 26.8288 | J20: =Revenue!J28*in_PayFee -> 30.510236 | ... AL20: =Revenue!AL28*in_PayFee -> 297.6115
A21: Marketing (content, SEO, ads, materials) | B21: EUR | C21: =CHOOSE(C$5,in_MktY1,in_MktY2,in_MktY3) -> 1500 | D21: =CHOOSE(D$5,in_MktY1,in_MktY2,in_MktY3) -> 1500 | E21: =CHOOSE(E$5,in_MktY1,in_MktY2,in_MktY3) -> 1500 | F21: =CHOOSE(F$5,in_MktY1,in_MktY2,in_MktY3) -> 1500 | G21: =CHOOSE(G$5,in_MktY1,in_MktY2,in_MktY3) -> 1500 | H21: =CHOOSE(H$5,in_MktY1,in_MktY2,in_MktY3) -> 1500 | I21: =CHOOSE(I$5,in_MktY1,in_MktY2,in_MktY3) -> 1500 | J21: =CHOOSE(J$5,in_MktY1,in_MktY2,in_MktY3) -> 1500 | ... AL21: =CHOOSE(AL$5,in_MktY1,in_MktY2,in_MktY3) -> 3500
A22: Travel & accountant events | B22: EUR | C22: =in_Travel -> 300 | D22: =in_Travel -> 300 | E22: =in_Travel -> 300 | F22: =in_Travel -> 300 | G22: =in_Travel -> 300 | H22: =in_Travel -> 300 | I22: =in_Travel -> 300 | J22: =in_Travel -> 300 | ... AL22: =in_Travel -> 300
A23: Accountant commissions (20% x 6 months) | B23: EUR | C23: =in_CommRate*Revenue!C25*SUMPRODUCT((Revenue!$C$3:$AL$3>C$3-in_CommMonths)*(Revenue!$C$3:$AL$3<=C$3)*Revenue!$C$19:$AL$19) -> 0 | D23: =in_CommRate*Revenue!D25*SUMPRODUCT((Revenue!$C$3:$AL$3>D$3-in_CommMonths)*(Revenue!$C$3:$AL$3<=D$3)*Revenue!$C$19:$AL$19) -> 0 | E23: =in_CommRate*Revenue!E25*SUMPRODUCT((Revenue!$C$3:$AL$3>E$3-in_CommMonths)*(Revenue!$C$3:$AL$3<=E$3)*Revenue!$C$19:$AL$19) -> 0 | F23: =in_CommRate*Revenue!F25*SUMPRODUCT((Revenue!$C$3:$AL$3>F$3-in_CommMonths)*(Revenue!$C$3:$AL$3<=F$3)*Revenue!$C$19:$AL$19) -> 57.12 | G23: =in_CommRate*Revenue!G25*SUMPRODUCT((Revenue!$C$3:$AL$3>G$3-in_CommMonths)*(Revenue!$C$3:$AL$3<=G$3)*Revenue!$C$19:$AL$19) -> 57.12 | H23: =in_CommRate*Revenue!H25*SUMPRODUCT((Revenue!$C$3:$AL$3>H$3-in_CommMonths)*(Revenue!$C$3:$AL$3<=H$3)*Revenue!$C$19:$AL$19) -> 63.784 | I23: =in_CommRate*Revenue!I25*SUMPRODUCT((Revenue!$C$3:$AL$3>I$3-in_CommMonths)*(Revenue!$C$3:$AL$3<=I$3)*Revenue!$C$19:$AL$19) -> 71.4 | J23: =in_CommRate*Revenue!J25*SUMPRODUCT((Revenue!$C$3:$AL$3>J$3-in_CommMonths)*(Revenue!$C$3:$AL$3<=J$3)*Revenue!$C$19:$AL$19) -> 79.968 | ... AL23: =in_CommRate*Revenue!AL25*SUMPRODUCT((Revenue!$C$3:$AL$3>AL$3-in_CommMonths)*(Revenue!$C$3:$AL$3<=AL$3)*Revenue!$C$19:$AL$19) -> 510.09588
A24: Coworking (Timiș) | B24: EUR | C24: =in_Office -> 200 | D24: =in_Office -> 200 | E24: =in_Office -> 200 | F24: =in_Office -> 200 | G24: =in_Office -> 200 | H24: =in_Office -> 200 | I24: =in_Office -> 200 | J24: =in_Office -> 200 | ... AL24: =in_Office -> 200
A25: Professional liability insurance | B25: EUR | C25: =in_Insurance -> 100 | D25: =in_Insurance -> 100 | E25: =in_Insurance -> 100 | F25: =in_Insurance -> 100 | G25: =in_Insurance -> 100 | H25: =in_Insurance -> 100 | I25: =in_Insurance -> 100 | J25: =in_Insurance -> 100 | ... AL25: =in_Insurance -> 100
A26: Bookkeeping, bank, admin | B26: EUR | C26: =in_Admin -> 200 | D26: =in_Admin -> 200 | E26: =in_Admin -> 200 | F26: =in_Admin -> 200 | G26: =in_Admin -> 200 | H26: =in_Admin -> 200 | I26: =in_Admin -> 200 | J26: =in_Admin -> 200 | ... AL26: =in_Admin -> 200
A27: Legal: round, T&C, DPA, IP assignment (one-off) | B27: EUR | C27: =IF(AND(C$3>=in_LegalStart,C$3<=in_LegalEnd),in_LegalAmt/(in_LegalEnd-in_LegalStart+1),0) -> 2500 | D27: =IF(AND(D$3>=in_LegalStart,D$3<=in_LegalEnd),in_LegalAmt/(in_LegalEnd-in_LegalStart+1),0) -> 2500 | E27: =IF(AND(E$3>=in_LegalStart,E$3<=in_LegalEnd),in_LegalAmt/(in_LegalEnd-in_LegalStart+1),0) -> 0 | F27: =IF(AND(F$3>=in_LegalStart,F$3<=in_LegalEnd),in_LegalAmt/(in_LegalEnd-in_LegalStart+1),0) -> 0 | G27: =IF(AND(G$3>=in_LegalStart,G$3<=in_LegalEnd),in_LegalAmt/(in_LegalEnd-in_LegalStart+1),0) -> 0 | H27: =IF(AND(H$3>=in_LegalStart,H$3<=in_LegalEnd),in_LegalAmt/(in_LegalEnd-in_LegalStart+1),0) -> 0 | I27: =IF(AND(I$3>=in_LegalStart,I$3<=in_LegalEnd),in_LegalAmt/(in_LegalEnd-in_LegalStart+1),0) -> 0 | J27: =IF(AND(J$3>=in_LegalStart,J$3<=in_LegalEnd),in_LegalAmt/(in_LegalEnd-in_LegalStart+1),0) -> 0 | ... AL27: =IF(AND(AL$3>=in_LegalStart,AL$3<=in_LegalEnd),in_LegalAmt/(in_LegalEnd-in_LegalStart+1),0) -> 0
A28: Payroll legal-value validation (one-off) | B28: EUR | C28: =IF(AND(C$3>=in_PayrollValStart,C$3<=in_PayrollValEnd),in_PayrollValAmt/(in_PayrollValEnd-in_PayrollValStart+1),0) -> 0 | D28: =IF(AND(D$3>=in_PayrollValStart,D$3<=in_PayrollValEnd),in_PayrollValAmt/(in_PayrollValEnd-in_PayrollValStart+1),0) -> 2000 | E28: =IF(AND(E$3>=in_PayrollValStart,E$3<=in_PayrollValEnd),in_PayrollValAmt/(in_PayrollValEnd-in_PayrollValStart+1),0) -> 2000 | F28: =IF(AND(F$3>=in_PayrollValStart,F$3<=in_PayrollValEnd),in_PayrollValAmt/(in_PayrollValEnd-in_PayrollValStart+1),0) -> 2000 | G28: =IF(AND(G$3>=in_PayrollValStart,G$3<=in_PayrollValEnd),in_PayrollValAmt/(in_PayrollValEnd-in_PayrollValStart+1),0) -> 2000 | H28: =IF(AND(H$3>=in_PayrollValStart,H$3<=in_PayrollValEnd),in_PayrollValAmt/(in_PayrollValEnd-in_PayrollValStart+1),0) -> 0 | I28: =IF(AND(I$3>=in_PayrollValStart,I$3<=in_PayrollValEnd),in_PayrollValAmt/(in_PayrollValEnd-in_PayrollValStart+1),0) -> 0 | J28: =IF(AND(J$3>=in_PayrollValStart,J$3<=in_PayrollValEnd),in_PayrollValAmt/(in_PayrollValEnd-in_PayrollValStart+1),0) -> 0 | ... AL28: =IF(AND(AL$3>=in_PayrollValStart,AL$3<=in_PayrollValEnd),in_PayrollValAmt/(in_PayrollValEnd-in_PayrollValStart+1),0) -> 0
A29: Accessibility audit EN 301 549 (one-off) | B29: EUR | C29: =IF(AND(C$3>=in_A11yStart,C$3<=in_A11yEnd),in_A11yAmt/(in_A11yEnd-in_A11yStart+1),0) -> 0 | D29: =IF(AND(D$3>=in_A11yStart,D$3<=in_A11yEnd),in_A11yAmt/(in_A11yEnd-in_A11yStart+1),0) -> 0 | E29: =IF(AND(E$3>=in_A11yStart,E$3<=in_A11yEnd),in_A11yAmt/(in_A11yEnd-in_A11yStart+1),0) -> 0 | F29: =IF(AND(F$3>=in_A11yStart,F$3<=in_A11yEnd),in_A11yAmt/(in_A11yEnd-in_A11yStart+1),0) -> 0 | G29: =IF(AND(G$3>=in_A11yStart,G$3<=in_A11yEnd),in_A11yAmt/(in_A11yEnd-in_A11yStart+1),0) -> 1500 | H29: =IF(AND(H$3>=in_A11yStart,H$3<=in_A11yEnd),in_A11yAmt/(in_A11yEnd-in_A11yStart+1),0) -> 1500 | I29: =IF(AND(I$3>=in_A11yStart,I$3<=in_A11yEnd),in_A11yAmt/(in_A11yEnd-in_A11yStart+1),0) -> 0 | J29: =IF(AND(J$3>=in_A11yStart,J$3<=in_A11yEnd),in_A11yAmt/(in_A11yEnd-in_A11yStart+1),0) -> 0 | ... AL29: =IF(AND(AL$3>=in_A11yStart,AL$3<=in_A11yEnd),in_A11yAmt/(in_A11yEnd-in_A11yStart+1),0) -> 0
A30: Penetration test (one-off) | B30: EUR | C30: =IF(AND(C$3>=in_PentestStart,C$3<=in_PentestEnd),in_PentestAmt/(in_PentestEnd-in_PentestStart+1),0) -> 0 | D30: =IF(AND(D$3>=in_PentestStart,D$3<=in_PentestEnd),in_PentestAmt/(in_PentestEnd-in_PentestStart+1),0) -> 0 | E30: =IF(AND(E$3>=in_PentestStart,E$3<=in_PentestEnd),in_PentestAmt/(in_PentestEnd-in_PentestStart+1),0) -> 0 | F30: =IF(AND(F$3>=in_PentestStart,F$3<=in_PentestEnd),in_PentestAmt/(in_PentestEnd-in_PentestStart+1),0) -> 0 | G30: =IF(AND(G$3>=in_PentestStart,G$3<=in_PentestEnd),in_PentestAmt/(in_PentestEnd-in_PentestStart+1),0) -> 0 | H30: =IF(AND(H$3>=in_PentestStart,H$3<=in_PentestEnd),in_PentestAmt/(in_PentestEnd-in_PentestStart+1),0) -> 0 | I30: =IF(AND(I$3>=in_PentestStart,I$3<=in_PentestEnd),in_PentestAmt/(in_PentestEnd-in_PentestStart+1),0) -> 0 | J30: =IF(AND(J$3>=in_PentestStart,J$3<=in_PentestEnd),in_PentestAmt/(in_PentestEnd-in_PentestStart+1),0) -> 0 | ... AL30: =IF(AND(AL$3>=in_PentestStart,AL$3<=in_PentestEnd),in_PentestAmt/(in_PentestEnd-in_PentestStart+1),0) -> 0
A31: Total operating expenses | B31: EUR | C31: =SUM(C17:C30) -> 5400 | D31: =SUM(D17:D30) -> 7409.3483 | E31: =SUM(E17:E30) -> 4918.4161 | F31: =SUM(F17:F30) -> 4999.0438 | G31: =SUM(G17:G30) -> 6507.1344 | H31: =SUM(H17:H30) -> 4523.3626 | I31: =SUM(I17:I30) -> 3040.5011 | J31: =SUM(J17:J30) -> 3058.5511 | ... AL31: =SUM(AL17:AL30) -> 6133.0368
A32: Contingency | B32: EUR | C32: =(C13+C31)*in_Contingency -> 372.25 | D32: =(D13+D31)*in_Contingency -> 472.71741 | E32: =(E13+E31)*in_Contingency -> 399.2958 | F32: =(F13+F31)*in_Contingency -> 403.32719 | G32: =(G13+G31)*in_Contingency -> 478.73172 | H32: =(H13+H31)*in_Contingency -> 379.54313 | I32: =(I13+I31)*in_Contingency -> 341.18755 | J32: =(J13+J31)*in_Contingency -> 342.09005 | ... AL32: =(AL13+AL31)*in_Contingency -> 751.93781
A34: TOTAL COSTS | B34: EUR | C34: =C13+C31+C32 -> 7817.25 | D34: =D13+D31+D32 -> 9927.0657 | E34: =E13+E31+E32 -> 8385.2119 | F34: =F13+F31+F32 -> 8469.871 | G34: =G13+G31+G32 -> 10053.366 | H34: =H13+H31+H32 -> 7970.4057 | I34: =I13+I31+I32 -> 7164.9386 | J34: =J13+J31+J32 -> 7183.8911 | ... AL34: =AL13+AL31+AL32 -> 15790.694

Sheet P&L & Cash
A1: P&L and cash (EUR, PROJECTION, selected scenario)
A2: Gross profit treats hosting, payment fees and the onboarding/support salary as cost of revenue. Break-even = first month with net cash flow >= 0.
A3: Month # | C3: =Revenue!C3 -> 1 | D3: =Revenue!D3 -> 2 | E3: =Revenue!E3 -> 3 | F3: =Revenue!F3 -> 4 | G3: =Revenue!G3 -> 5 | H3: =Revenue!H3 -> 6 | I3: =Revenue!I3 -> 7 | J3: =Revenue!J3 -> 8 | ... AL3: =Revenue!AL3 -> 36
A4: Month | C4: =Revenue!C4 -> 46388 | D4: =Revenue!D4 -> 46419 | E4: =Revenue!E4 -> 46447 | F4: =Revenue!F4 -> 46478 | G4: =Revenue!G4 -> 46508 | H4: =Revenue!H4 -> 46539 | I4: =Revenue!I4 -> 46569 | J4: =Revenue!J4 -> 46600 | ... AL4: =Revenue!AL4 -> 47453
A5: Model year | C5: =Revenue!C5 -> 1 | D5: =Revenue!D5 -> 1 | E5: =Revenue!E5 -> 1 | F5: =Revenue!F5 -> 1 | G5: =Revenue!G5 -> 1 | H5: =Revenue!H5 -> 1 | I5: =Revenue!I5 -> 1 | J5: =Revenue!J5 -> 1 | ... AL5: =Revenue!AL5 -> 3
A7: Profit and loss
A8: Revenue | B8: EUR | C8: =Revenue!C28 -> 0 | D8: =Revenue!D28 -> 181.475 | E8: =Revenue!E28 -> 357.50575 | F8: =Revenue!F28 -> 813.85558 | G8: =Revenue!G28 -> 970.91491 | H8: =Revenue!H28 -> 1156.5825 | I8: =Revenue!I28 -> 1341.44 | J8: =Revenue!J28 -> 1525.5118 | ... AL8: =Revenue!AL28 -> 14880.575
A9: Cost of revenue (hosting, fees, onboarding & support) | B9: EUR | C9: =Costs!C17+Costs!C18+Costs!C20+Costs!C11 -> 350 | D9: =Costs!D17+Costs!D18+Costs!D20+Costs!D11 -> 359.34825 | E9: =Costs!E17+Costs!E18+Costs!E20+Costs!E11 -> 368.41605 | F9: =Costs!F17+Costs!F18+Costs!F20+Costs!F11 -> 391.92382 | G9: =Costs!G17+Costs!G18+Costs!G20+Costs!G11 -> 400.01436 | H9: =Costs!H17+Costs!H18+Costs!H20+Costs!H11 -> 409.57858 | I9: =Costs!I17+Costs!I18+Costs!I20+Costs!I11 -> 1134.8511 | J9: =Costs!J17+Costs!J18+Costs!J20+Costs!J11 -> 1144.3331 | ... AL9: =Costs!AL17+Costs!AL18+Costs!AL20+Costs!AL11 -> 2651.1697
A10: Gross profit | B10: EUR | C10: =C8-C9 -> -350 | D10: =D8-D9 -> -177.87325 | E10: =E8-E9 -> -10.910303 | F10: =F8-F9 -> 421.93176 | G10: =G8-G9 -> 570.90055 | H10: =H8-H9 -> 747.00389 | I10: =I8-I9 -> 206.58892 | J10: =J8-J9 -> 381.1787 | ... AL10: =AL8-AL9 -> 12229.405
A11: Gross margin | B11: % | C11: =IF(C8>0,C10/C8,0) -> 0 | D11: =IF(D8>0,D10/D8,0) -> -0.98015291 | E11: =IF(E8>0,E10/E8,0) -> -0.030517838 | F11: =IF(F8>0,F10/F8,0) -> 0.51843566 | G11: =IF(G8>0,G10/G8,0) -> 0.58800266 | H11: =IF(H8>0,H10/H8,0) -> 0.6458717 | I11: =IF(I8>0,I10/I8,0) -> 0.15400534 | J11: =IF(J8>0,J10/J8,0) -> 0.24986939 | ... AL11: =IF(AL8>0,AL10/AL8,0) -> 0.82183688
A12: R&D (co-founders, developer, tools) | B12: EUR | C12: =Costs!C8+Costs!C9+Costs!C12+Costs!C19 -> 2295 | D12: =Costs!D8+Costs!D9+Costs!D12+Costs!D19 -> 2295 | E12: =Costs!E8+Costs!E9+Costs!E12+Costs!E19 -> 2295 | F12: =Costs!F8+Costs!F9+Costs!F12+Costs!F19 -> 2295 | G12: =Costs!G8+Costs!G9+Costs!G12+Costs!G19 -> 2295 | H12: =Costs!H8+Costs!H9+Costs!H12+Costs!H19 -> 2295 | I12: =Costs!I8+Costs!I9+Costs!I12+Costs!I19 -> 2295 | J12: =Costs!J8+Costs!J9+Costs!J12+Costs!J19 -> 2295 | ... AL12: =Costs!AL8+Costs!AL9+Costs!AL12+Costs!AL19 -> 5322.8781
A13: Sales & marketing (partner manager, marketing, travel, commissions) | B13: EUR | C13: =Costs!C10+Costs!C21+Costs!C22+Costs!C23 -> 1800 | D13: =Costs!D10+Costs!D21+Costs!D22+Costs!D23 -> 1800 | E13: =Costs!E10+Costs!E21+Costs!E22+Costs!E23 -> 2822.5 | F13: =Costs!F10+Costs!F21+Costs!F22+Costs!F23 -> 2879.62 | G13: =Costs!G10+Costs!G21+Costs!G22+Costs!G23 -> 2879.62 | H13: =Costs!H10+Costs!H21+Costs!H22+Costs!H23 -> 2886.284 | I13: =Costs!I10+Costs!I21+Costs!I22+Costs!I23 -> 2893.9 | J13: =Costs!J10+Costs!J21+Costs!J22+Costs!J23 -> 2902.468 | ... AL13: =Costs!AL10+Costs!AL21+Costs!AL22+Costs!AL23 -> 6564.7084
A14: G&A (legal, validation, compliance, office, insurance, admin, contingency) | B14: EUR | C14: =Costs!C24+Costs!C25+Costs!C26+Costs!C27+Costs!C28+Costs!C29+Costs!C30+Costs!C32 -> 3372.25 | D14: =Costs!D24+Costs!D25+Costs!D26+Costs!D27+Costs!D28+Costs!D29+Costs!D30+Costs!D32 -> 5472.7174 | E14: =Costs!E24+Costs!E25+Costs!E26+Costs!E27+Costs!E28+Costs!E29+Costs!E30+Costs!E32 -> 2899.2958 | F14: =Costs!F24+Costs!F25+Costs!F26+Costs!F27+Costs!F28+Costs!F29+Costs!F30+Costs!F32 -> 2903.3272 | G14: =Costs!G24+Costs!G25+Costs!G26+Costs!G27+Costs!G28+Costs!G29+Costs!G30+Costs!G32 -> 4478.7317 | H14: =Costs!H24+Costs!H25+Costs!H26+Costs!H27+Costs!H28+Costs!H29+Costs!H30+Costs!H32 -> 2379.5431 | I14: =Costs!I24+Costs!I25+Costs!I26+Costs!I27+Costs!I28+Costs!I29+Costs!I30+Costs!I32 -> 841.18755 | J14: =Costs!J24+Costs!J25+Costs!J26+Costs!J27+Costs!J28+Costs!J29+Costs!J30+Costs!J32 -> 842.09005 | ... AL14: =Costs!AL24+Costs!AL25+Costs!AL26+Costs!AL27+Costs!AL28+Costs!AL29+Costs!AL30+Costs!AL32 -> 1251.9378
A15: EBITDA | B15: EUR | C15: =C10-C12-C13-C14 -> -7817.25 | D15: =D10-D12-D13-D14 -> -9745.5907 | E15: =E10-E12-E13-E14 -> -8027.7061 | F15: =F10-F12-F13-F14 -> -7656.0154 | G15: =G10-G12-G13-G14 -> -9082.4512 | H15: =H10-H12-H13-H14 -> -6813.8232 | I15: =I10-I12-I13-I14 -> -5823.4986 | J15: =J10-J12-J13-J14 -> -5658.3794 | ... AL15: =AL10-AL12-AL13-AL14 -> -910.11883
A16: Check: EBITDA = revenue - total costs (should be 0) | B16: EUR | C16: =ROUND(C15-(C8-Costs!C34),2) -> 0 | D16: =ROUND(D15-(D8-Costs!D34),2) -> 0 | E16: =ROUND(E15-(E8-Costs!E34),2) -> 0 | F16: =ROUND(F15-(F8-Costs!F34),2) -> 0 | G16: =ROUND(G15-(G8-Costs!G34),2) -> 0 | H16: =ROUND(H15-(H8-Costs!H34),2) -> 0 | I16: =ROUND(I15-(I8-Costs!I34),2) -> 0 | J16: =ROUND(J15-(J8-Costs!J34),2) -> 0 | ... AL16: =ROUND(AL15-(AL8-Costs!AL34),2) -> 0
A17: Tax (micro on revenue, or profit tax) | B17: EUR | C17: =IF(in_TaxRegime=1,in_MicroRate*C8,MAX(0,in_ProfitTax*C15)) -> 0 | D17: =IF(in_TaxRegime=1,in_MicroRate*D8,MAX(0,in_ProfitTax*D15)) -> 1.81475 | E17: =IF(in_TaxRegime=1,in_MicroRate*E8,MAX(0,in_ProfitTax*E15)) -> 3.5750575 | F17: =IF(in_TaxRegime=1,in_MicroRate*F8,MAX(0,in_ProfitTax*F15)) -> 8.1385558 | G17: =IF(in_TaxRegime=1,in_MicroRate*G8,MAX(0,in_ProfitTax*G15)) -> 9.7091491 | H17: =IF(in_TaxRegime=1,in_MicroRate*H8,MAX(0,in_ProfitTax*H15)) -> 11.565825 | I17: =IF(in_TaxRegime=1,in_MicroRate*I8,MAX(0,in_ProfitTax*I15)) -> 13.4144 | J17: =IF(in_TaxRegime=1,in_MicroRate*J8,MAX(0,in_ProfitTax*J15)) -> 15.255118 | ... AL17: =IF(in_TaxRegime=1,in_MicroRate*AL8,MAX(0,in_ProfitTax*AL15)) -> 148.80575
A18: Net result = operating cash flow | B18: EUR | C18: =C15-C17 -> -7817.25 | D18: =D15-D17 -> -9747.4054 | E18: =E15-E17 -> -8031.2812 | F18: =F15-F17 -> -7664.154 | G18: =G15-G17 -> -9092.1603 | H18: =H15-H17 -> -6825.3891 | I18: =I15-I17 -> -5836.913 | J18: =J15-J17 -> -5673.6345 | ... AL18: =AL15-AL17 -> -1058.9246
A20: Cash
A21: Opening cash | B21: EUR | C21: =in_OpeningCash -> 0 | D21: =C23 -> 142182.75 | E21: =D23 -> 132435.34 | F21: =E23 -> 124404.06 | G21: =F23 -> 116739.91 | H21: =G23 -> 107647.75 | I21: =H23 -> 100822.36 | J21: =I23 -> 94985.447 | K21: =J23 -> 89311.813 | ... AL21: =AK23 -> -49647.477
A22: Funding received (pre-seed round) | B22: EUR | C22: =IF(C$3=in_FundingMonth,in_Round,0) -> 150000 | D22: =IF(D$3=in_FundingMonth,in_Round,0) -> 0 | E22: =IF(E$3=in_FundingMonth,in_Round,0) -> 0 | F22: =IF(F$3=in_FundingMonth,in_Round,0) -> 0 | G22: =IF(G$3=in_FundingMonth,in_Round,0) -> 0 | H22: =IF(H$3=in_FundingMonth,in_Round,0) -> 0 | I22: =IF(I$3=in_FundingMonth,in_Round,0) -> 0 | J22: =IF(J$3=in_FundingMonth,in_Round,0) -> 0 | ... AL22: =IF(AL$3=in_FundingMonth,in_Round,0) -> 0
A23: Closing cash | B23: EUR | C23: =C21+C22+C18 -> 142182.75 | D23: =D21+D22+D18 -> 132435.34 | E23: =E21+E22+E18 -> 124404.06 | F23: =F21+F22+F18 -> 116739.91 | G23: =G21+G22+G18 -> 107647.75 | H23: =H21+H22+H18 -> 100822.36 | I23: =I21+I22+I18 -> 94985.447 | J23: =J21+J22+J18 -> 89311.813 | ... AL23: =AL21+AL22+AL18 -> -50706.401
A24: Cumulative total costs (for zero-revenue runway) | B24: EUR | C24: =Costs!C34 -> 7817.25 | D24: =C24+Costs!D34 -> 17744.316 | E24: =D24+Costs!E34 -> 26129.528 | F24: =E24+Costs!F34 -> 34599.399 | G24: =F24+Costs!G34 -> 44652.765 | H24: =G24+Costs!H34 -> 52623.17 | I24: =H24+Costs!I34 -> 59788.109 | J24: =I24+Costs!J34 -> 66972 | K24: =J24+Costs!K34 -> 74175.802 | ... AL24: =AK24+Costs!AL34 -> 405034.54
A25: Cumulative operating cash flow | B25: EUR | C25: =C18 -> -7817.25 | D25: =C25+D18 -> -17564.655 | E25: =D25+E18 -> -25595.937 | F25: =E25+F18 -> -33260.091 | G25: =F25+G18 -> -42352.251 | H25: =G25+H18 -> -49177.64 | I25: =H25+I18 -> -55014.553 | J25: =I25+J18 -> -60688.187 | K25: =J25+K18 -> -66200.256 | ... AL25: =AK25+AL18 -> -200706.4
A26: Flag: cash below zero | B26: 1/0 | C26: =IF(C23<0,1,0) -> 0 | D26: =IF(D23<0,1,0) -> 0 | E26: =IF(E23<0,1,0) -> 0 | F26: =IF(F23<0,1,0) -> 0 | G26: =IF(G23<0,1,0) -> 0 | H26: =IF(H23<0,1,0) -> 0 | I26: =IF(I23<0,1,0) -> 0 | J26: =IF(J23<0,1,0) -> 0 | ... AL26: =IF(AL23<0,1,0) -> 1
A27: Flag: net cash flow >= 0 | B27: 1/0 | C27: =IF(C18>=0,1,0) -> 0 | D27: =IF(D18>=0,1,0) -> 0 | E27: =IF(E18>=0,1,0) -> 0 | F27: =IF(F18>=0,1,0) -> 0 | G27: =IF(G18>=0,1,0) -> 0 | H27: =IF(H18>=0,1,0) -> 0 | I27: =IF(I18>=0,1,0) -> 0 | J27: =IF(J18>=0,1,0) -> 0 | ... AL27: =IF(AL18>=0,1,0) -> 0
A28: Closing cash - option A (VV ticket + minimum private match only) | B28: EUR | C28: =C23-(in_Round-in_OptionA)*IF(C$3>=in_FundingMonth,1,0) -> 140682.75 | D28: =D23-(in_Round-in_OptionA)*IF(D$3>=in_FundingMonth,1,0) -> 130935.34 | E28: =E23-(in_Round-in_OptionA)*IF(E$3>=in_FundingMonth,1,0) -> 122904.06 | F28: =F23-(in_Round-in_OptionA)*IF(F$3>=in_FundingMonth,1,0) -> 115239.91 | G28: =G23-(in_Round-in_OptionA)*IF(G$3>=in_FundingMonth,1,0) -> 106147.75 | H28: =H23-(in_Round-in_OptionA)*IF(H$3>=in_FundingMonth,1,0) -> 99322.36 | I28: =I23-(in_Round-in_OptionA)*IF(I$3>=in_FundingMonth,1,0) -> 93485.447 | J28: =J23-(in_Round-in_OptionA)*IF(J$3>=in_FundingMonth,1,0) -> 87811.813 | ... AL28: =AL23-(in_Round-in_OptionA)*IF(AL$3>=in_FundingMonth,1,0) -> -52206.401
A29: Flag: option A cash below zero | B29: 1/0 | C29: =IF(C28<0,1,0) -> 0 | D29: =IF(D28<0,1,0) -> 0 | E29: =IF(E28<0,1,0) -> 0 | F29: =IF(F28<0,1,0) -> 0 | G29: =IF(G28<0,1,0) -> 0 | H29: =IF(H28<0,1,0) -> 0 | I29: =IF(I28<0,1,0) -> 0 | J29: =IF(J28<0,1,0) -> 0 | ... AL29: =IF(AL28<0,1,0) -> 1
A30: Running minimum of cumulative operating cash flow (for round-size tests) | B30: EUR | C30: =C25 -> -7817.25 | D30: =MIN(C30,D25) -> -17564.655 | E30: =MIN(D30,E25) -> -25595.937 | F30: =MIN(E30,F25) -> -33260.091 | G30: =MIN(F30,G25) -> -42352.251 | H30: =MIN(G30,H25) -> -49177.64 | I30: =MIN(H30,I25) -> -55014.553 | J30: =MIN(I30,J25) -> -60688.187 | K30: =MIN(J30,K25) -> -66200.256 | ... AL30: =MIN(AK30,AL25) -> -200706.4
A31: Summary (selected scenario)
A32: Option A round: VV ticket + minimum private co-investment | C32: =in_VVTicket*(1+in_MinPrivatePct) -> 148500 | E32: VV ticket alone is not allowed: VV requires >=10% independent private money.
A33: Runway with ZERO revenue (target round) | C33: =COUNTIF('P&L & Cash'!$C$24:$AL$24,"<="&(in_Round+in_OpeningCash)) -> 16 | E33: Months the round pays every planned cost even if no customer ever pays. Basis of the round size.
A34: Runway with ZERO revenue (option A) | C34: =COUNTIF('P&L & Cash'!$C$24:$AL$24,"<="&(in_OptionA+in_OpeningCash)) -> 16
A35: Runway on plan (months until cash < 0) | C35: =IF(MAX('P&L & Cash'!$C$26:$AL$26)=0,"> 36",MATCH(1,'P&L & Cash'!$C$26:$AL$26,0)-1) -> 24 | E35: '> 36' = cash never goes negative within the model horizon.
A36: Runway on plan, option A | C36: =IF(MAX('P&L & Cash'!$C$29:$AL$29)=0,"> 36",MATCH(1,'P&L & Cash'!$C$29:$AL$29,0)-1) -> 23
A37: Break-even month (first month net cash flow >= 0) | C37: =IF(MAX('P&L & Cash'!$C$27:$AL$27)=0,"not within 36 months",MATCH(1,'P&L & Cash'!$C$27:$AL$27,0)) -> not within 36 months | D37: =IF(ISNUMBER(C37),INDEX(Revenue!$C$4:$AL$4,1,C37),"-") -> - | E37: model month #; date in next cell
A38: Cash low point | C38: =MIN('P&L & Cash'!$C$23:$AL$23) -> -50706.401
A39: Cash low point month | C39: =MATCH(in_CashLow,'P&L & Cash'!$C$23:$AL$23,0) -> 36 | D39: =INDEX(Revenue!$C$4:$AL$4,1,C39) -> 47453
A40: Cash low point, option A | C40: =MIN('P&L & Cash'!$C$28:$AL$28) -> -52206.401
A41: Cash at month 36 | C41: =AL23 -> -50706.401
A42: Revenue, months 1-12 | C42: =SUMIF(Revenue!$C$5:$AL$5,1,'P&L & Cash'!$C$8:$AL$8) -> 14275.146
...

Sheet Unit economics
A1: Unit economics (PROJECTION, selected scenario, model year in_UEYear)
A2: Computed over one model year (default year 2 = Jan-Dec 2028). Benchmarks: ChartMogul (churn) and Aleph (CAC payback, secondary); URLs on sheet Sources.
A4: Metric | B4: Value | C4: Definition / benchmark
A5: Revenue in the year | B5: =SUMIF(Revenue!$C$5:$AL$5,in_UEYear,Revenue!$C$28:$AL$28) -> 56648.447
A6: Customer-months in the year | B6: =SUMIF(Revenue!$C$5:$AL$5,in_UEYear,Revenue!$C$21:$AL$21) -> 1133.4223 | C6: sum of end-of-month paying customers
A7: ARPA (average revenue per account) | B7: =IF(in_UE_CustMonths>0,in_UE_Rev/in_UE_CustMonths,0) -> 49.98 | C7: EUR per paying company per month (flat price per company, not per employee)
A8: Variable cost per customer | B8: =in_InfraVar+in_PayFee*in_ARPA -> 2.4996 | C8: variable infrastructure + payment fees
A9: Contribution margin (per-customer gross margin) | B9: =IF(in_ARPA>0,(in_ARPA-in_VarCost)/in_ARPA,0) -> 0.949988 | C9: Gross margin used in LTV. Excludes fixed hosting and support salary.
A10: Gross margin, P&L basis | B10: =IF(in_UE_Rev>0,SUMIF(Revenue!$C$5:$AL$5,in_UEYear,'P&L & Cash'!$C$10:$AL$10)/in_UE_Rev,0) -> 0.7166462 | C10: After fixed hosting and the onboarding/support salary - low while the base is small.
A11: Sales & marketing spend in the year | B11: =SUMIF(Revenue!$C$5:$AL$5,in_UEYear,'P&L & Cash'!$C$13:$AL$13) -> 60990.35 | C11: partner manager + marketing + travel + accountant commissions
A12: New paying customers in the year | B12: =SUMIF(Revenue!$C$5:$AL$5,in_UEYear,Revenue!$C$18:$AL$18) -> 122.775
A13: Blended CAC | B13: =IF(in_UE_New>0,in_UE_SnM/in_UE_New,0) -> 496.76522 | C13: S&M spend / new paying customers (fully loaded, incl. salary)
A14: Paid-ads CAC (media only) | B14: =in_CostPerTrial/in_TrialConv -> 320 | C14: cost per trial / trial conversion
A15: Monthly logo churn | B15: =in_Churn -> 0.03 | C15: Benchmark: ChartMogul median 6.1%/month for ARPA < US$25
A16: Expected customer lifetime | B16: =IF(in_Churn>0,1/in_Churn,0) -> 33.333333 | C16: 1 / churn
A17: LTV (contribution basis) | B17: =IF(in_Churn>0,in_ARPA*in_CM/in_Churn,0) -> 1582.68 | C17: ARPA x contribution margin / churn
A18: LTV / CAC | B18: =IF(in_CAC>0,in_LTV/in_CAC,0) -> 3.1859718 | C18: > 3x usually considered healthy
A19: CAC payback | B19: =IF(in_ARPA*in_CM>0,in_CAC/(in_ARPA*in_CM),0) -> 10.462532 | C19: Benchmark SMB SaaS: median ~11 months, healthy 6-14; 3-9 typical below US$5k ACV, so ours is above that (Aleph, secondary source)

Sheet Scenarios
A1: Scenarios - key growth drivers
A2: Blue = input. The scenario in use is chosen on Cover!C8 (1 Base, 2 Conservative, 3 Upside); Assumptions picks the matching column with INDEX. All values are ASSUMPTIONS / PROJECTIONS.
A4: Driver | B4: Unit | C4: Base | D4: Conservative | E4: Upside | F4: Note / source
A5: Accountant practices that join the pilot | B5: practices | C5: 6 | D5: 3 | E5: 10 | F5: Pilot offers 10 places, sign-up until 15 Nov 2026 (administrativo.ro/pentru-contabili). Zero signed on 6 Oct 2026 -> base assumes 6. ASSUMPTION.
A6: Client companies per pilot practice | B6: firms | C6: 2 | D6: 1.5 | E6: 2.5 | F6: Pilot allows 1-3 client companies per practice (administrativo.ro/pentru-contabili). ASSUMPTION within that range.
A7: Pilot company -> paying customer (Apr 2027) | B7: % | C7: 0.5 | D7: 0.33 | E7: 0.7 | F7: Pilot is free until 31 Mar 2027 (administrativo.ro/pentru-contabili). Conversion not observed yet. ASSUMPTION.
A8: New accountant partners per month, year 1 (full-time partner manager) | B8: per month | C8: 2 | D8: 1 | E8: 3 | F8: Signed by the partner manager from in_PartnerStart; rate for a FULL-TIME manager, scaled by in_SalesFTE while the role is part-time (until in_SalesFullStart). ASSUMPTION (~18,400 practices in RO: CECCAR 2025 report, as reported).
A9: New accountant partners per month, year 2 | B9: per month | C9: 3 | D9: 1.5 | E9: 5 | F9: ASSUMPTION.
A10: New accountant partners per month, year 3 | B10: per month | C10: 4 | D10: 2 | E10: 6 | F10: ASSUMPTION.
A11: Firms referred per active partner per month | B11: firms | C11: 0.2 | D11: 0.12 | E11: 0.3 | F11: 0.20 = one referral every 5 months per partner. No sourced figure for clients per accountant. ASSUMPTION.
A12: Referred firm -> paying customer | B12: % | C12: 0.5 | D12: 0.4 | E12: 0.6 | F12: ASSUMPTION (warm referral by the firm's own accountant).
A13: Organic / SEO / direct trials per month, year 1 | B13: trials | C13: 4 | D13: 2 | E13: 8 | F13: Web traffic today ~7 genuine visitors/month, 201 GSC impressions since 2 Sep 2026 (pre-launch). ASSUMPTION.
A14: Organic / SEO / direct trials per month, year 2 | B14: trials | C14: 12 | D14: 6 | E14: 20 | F14: ASSUMPTION.
A15: Organic / SEO / direct trials per month, year 3 | B15: trials | C15: 20 | D15: 10 | E15: 35 | F15: ASSUMPTION.
A16: Trial -> paying customer (after free month) | B16: % | C16: 0.25 | D16: 0.15 | E16: 0.3 | F16: First month free for every configuration (administrativo.ro price list). ASSUMPTION, no observed data.
... A20: Month the developer is hired | B20: model month | C20: 25 | D20: 31 | E20: 19 | F20: AFTER the seed: seed raise starts at 100 paying customers (in_M100), ~5-6 months to close. Base Jan 2029; Upside Jul 2028 (100 customers sooner); Conservative Jul 2029 (seed trigger not reached - deliberately late). Not funded by the pre-seed. ASSUMPTION.
A23: Scenario results snapshot (PROJECTION)
A24: Values below were produced by recalculating this workbook once per scenario (model/build_model.py + model/recalc.sh) and pasted as values so that a reader can compare scenarios without switching. Live values for the selected scenario: 'P&L & Cash' and Cover.
A25: Output | B25: Unit | C25: Base | D25: Conservative | E25: Upside
A26: Paying customers, month 12 (Dec 2027) | B26: firms | C26: 47 | D26: 15 | E26: 103
A27: MRR, month 12 | B27: EUR | C27: 2254 | D27: 702 | E27: 4892
A28: Paying customers, month 24 (Dec 2028) | B28: firms | C28: 139 | D28: 39 | E28: 313
A29: MRR, month 24 | B29: EUR | C29: 6941 | D29: 1877 | E29: 16072
A30: Paying customers, month 36 (Dec 2029) | B30: firms | C30: 284 | D30: 74 | E30: 682
A31: MRR, month 36 | B31: EUR | C31: 14881 | D31: 3533 | E31: 37888
A32: ARR, month 36 | B32: EUR | C32: 178567 | D32: 42401 | E32: 454657
A33: Break-even month (first month net cash flow >= 0) | B33: model month | C33: not within 36 months | D33: not within 36 months | E33: 22
A34: Cash low point | B34: EUR | C34: -50706 | D34: -170735 | E34: 57773
A35: Cash at month 36 | B35: EUR | C35: -50706 | D35: -170735 | E35: 188830
A36: Month reaching 30 paying customers | B36: model month | C36: 8 | D36: 20 | E36: 4
A37: Month reaching 100 paying customers | B37: model month | C37: 20 | D37: not within 36 months | E37: 12
A38: Month reaching 300 paying customers | B38: model month | C38: not within 36 months | D38: not within 36 months | E38: 24

Sheet Use of funds
A1: Use of funds - pre-seed round
A2: Split = share of each category in planned spend over the zero-revenue runway (the months the round alone pays for), applied to the round. Revenue earned in that period extends the runway further.
A4: Round size | B4: =in_Round -> 150000
A5: Spend horizon = zero-revenue runway | B5: =in_RunwayZeroRev -> 16
A6: ending in | B6: =INDEX(Revenue!$C$4:$AL$4,1,B5) -> 46844
A8: Category | B8: Planned spend in horizon | C8: Allocated from round | D8: % | E8: What it buys
A9: Product & engineering (2 co-founders full time) | B9: =SUMPRODUCT((Revenue!$C$3:$AL$3<=$B$5)*Costs!$C$8:$AL$8)+SUMPRODUCT((Revenue!$C$3:$AL$3<=$B$5)*Costs!$C$9:$AL$9)+SUMPRODUCT((Revenue!$C$3:$AL$3<=$B$5)*Costs!$C$12:$AL$12) -> 33129 | C9: =IF($B$16>0,B9/$B$16*$B$4,0) -> 35344.677 | D9: =IF($B$4>0,C9/$B$4,0) -> 0.23563118 | E9: Both co-founders full time on lean salaries; the developer is hired after the seed (in_DevStart), outside this horizon in the base case. REGES-Online, payroll validation fixes, billing, mobile store release.
A10: Accountant channel & sales (partner manager, travel, commissions) | B10: =SUMPRODUCT((Revenue!$C$3:$AL$3<=$B$5)*Costs!$C$10:$AL$10)+SUMPRODUCT((Revenue!$C$3:$AL$3<=$B$5)*Costs!$C$22:$AL$22)+SUMPRODUCT((Revenue!$C$3:$AL$3<=$B$5)*Costs!$C$23:$AL$23) -> 24509.832 | C10: =IF($B$16>0,B10/$B$16*$B$4,0) -> 26149.057 | D10: =IF($B$4>0,C10/$B$4,0) -> 0.17432704 | E10: Partner manager (half time in year 1, full time from in_SalesFullStart) signing accounting practices; 20% x 6-month commissions.
A11: Customer onboarding & support | B11: =SUMPRODUCT((Revenue!$C$3:$AL$3<=$B$5)*Costs!$C$11:$AL$11) -> 7300.65 | C11: =IF($B$16>0,B11/$B$16*$B$4,0) -> 7788.9196 | D11: =IF($B$4>0,C11/$B$4,0) -> 0.051926131 | E11: Half-time specialist from in_SupportStart: employee import, company setup and accounting mapping for each new firm.
A12: Marketing (content, SEO, performance ads) | B12: =SUMPRODUCT((Revenue!$C$3:$AL$3<=$B$5)*Costs!$C$21:$AL$21) -> 28000 | C12: =IF($B$16>0,B12/$B$16*$B$4,0) -> 29872.648 | D12: =IF($B$4>0,C12/$B$4,0) -> 0.19915099 | E12: REGES-Online / timesheet keywords; accountant materials.
A13: Legal, payroll validation, compliance & security | B13: =SUMPRODUCT((Revenue!$C$3:$AL$3<=$B$5)*Costs!$C$27:$AL$27)+SUMPRODUCT((Revenue!$C$3:$AL$3<=$B$5)*Costs!$C$28:$AL$28)+SUMPRODUCT((Revenue!$C$3:$AL$3<=$B$5)*Costs!$C$29:$AL$29)+SUMPRODUCT((Revenue!$C$3:$AL$3<=$B$5)*Costs!$C$30:$AL$30)+SUMPRODUCT((Revenue!$C$3:$AL$3<=$B$5)*Costs!$C$25:$AL$25) -> 23600 | C13: =IF($B$16>0,B13/$B$16*$B$4,0) -> 25178.375 | D13: =IF($B$4>0,C13/$B$4,0) -> 0.16785583 | E13: Round documents, DPA, payroll legal values validated, EN 301 549 accessibility audit, pentest, liability insurance.
A14: Infrastructure & tools | B14: =SUMPRODUCT((Revenue!$C$3:$AL$3<=$B$5)*Costs!$C$17:$AL$17)+SUMPRODUCT((Revenue!$C$3:$AL$3<=$B$5)*Costs!$C$18:$AL$18)+SUMPRODUCT((Revenue!$C$3:$AL$3<=$B$5)*Costs!$C$19:$AL$19)+SUMPRODUCT((Revenue!$C$3:$AL$3<=$B$5)*Costs!$C$20:$AL$20) -> 10962.273 | C14: =IF($B$16>0,B14/$B$16*$B$4,0) -> 11695.433 | D14: =IF($B$4>0,C14/$B$4,0) -> 0.077969551 | E14: Hosting, separate production database, AI/dev tools, payment fees.
A15: Operations & contingency | B15: =SUMPRODUCT((Revenue!$C$3:$AL$3<=$B$5)*Costs!$C$24:$AL$24)+SUMPRODUCT((Revenue!$C$3:$AL$3<=$B$5)*Costs!$C$26:$AL$26)+SUMPRODUCT((Revenue!$C$3:$AL$3<=$B$5)*Costs!$C$32:$AL$32) -> 13095.088 | C15: =IF($B$16>0,B15/$B$16*$B$4,0) -> 13970.891 | D15: =IF($B$4>0,C15/$B$4,0) -> 0.093139273 | E15: Coworking in Timiș, bookkeeping, 5% contingency.
A16: Total | B16: =SUM(B9:B15) -> 140596.84 | C16: =SUM(C9:C15) -> 150000 | D16: =SUM(D9:D15) -> 1
A18: Round size test (selected scenario; same pre-money valuation)
A19: Round size tested | B19: EUR | C19: Runway, zero revenue | D19: Runway on plan | E19: Dilution at this pre-money
